from fastapi import status
from fastapi.exceptions import HTTPException
from sqlalchemy import text, Connection
from sqlalchemy.exc import SQLAlchemyError
from schemas.blog_schema import Blog, BlogData
from utils import util
from typing import List

def get_all_blogs(conn: Connection) -> List:
    try:
        query = """
        SELECT id, title, author, content, image_loc, modified_dt FROM blog;
        """
        result = conn.execute(text(query))
        all_blogs = [BlogData(id=row.id,
              title=row.title,
              author=row.author,
              content=util.truncate_text(row.content),
              image_loc=row.image_loc, 
              modified_dt=row.modified_dt) for row in result]
        
        result.close()
        return all_blogs
    except SQLAlchemyError as e:
        print(e)
        raise HTTPException(status_code=status.HTTP_503_SERVICE_UNAVAILABLE,
                            detail="요청하신 서비스가 잠시 내부적으로 문제가 발생하였습니다.")
    except Exception as e:
        print(e)
        raise HTTPException(status_code=status.HTTP_500_INTERNAL_SERVER_ERROR,
                            detail="알수없는 이유로 서비스 오류가 발생하였습니다")


def get_blog_by_id(conn: Connection, id: int):
    try:
        query = f"""
        SELECT id, title, author, content, image_loc, modified_dt from blog
        where id = :id
        """
        stmt = text(query)
        bind_stmt = stmt.bindparams(id=id)
        result = conn.execute(bind_stmt)
        # 만약에 한건도 찾지 못하면 오류를 던진다. 
        if result.rowcount == 0:
            raise HTTPException(status_code=status.HTTP_404_NOT_FOUND,
                                detail=f"해당 id {id}는(은) 존재하지 않습니다.")

        row = result.fetchone()
        blog = BlogData(id=row[0], title=row[1], author=row[2], 
                        content=row[3],
                        image_loc=row[4], modified_dt=row[5])
        
        result.close()
        return blog
    
    except SQLAlchemyError as e:
        print(e)
        raise HTTPException(status_code=status.HTTP_503_SERVICE_UNAVAILABLE,
                            detail="요청하신 서비스가 잠시 내부적으로 문제가 발생하였습니다.")
    except Exception as e:
        print(e)
        raise HTTPException(status_code=status.HTTP_500_INTERNAL_SERVER_ERROR,
                            detail="알수없는 이유로 서비스 오류가 발생하였습니다")

def create_blog(conn: Connection, title:str, author: str, content:str):
    try:
        query = f"""
        INSERT INTO blog(title, author, content, modified_dt)
        values ('{title}', '{author}', '{content}', now())
        """
        conn.execute(text(query))
        conn.commit()
        
    except SQLAlchemyError as e:
        print(e)
        conn.rollback()
        raise HTTPException(status_code=status.HTTP_400_BAD_REQUEST,
                            detail="요청데이터가 제대로 전달되지 않았습니다.")

def update_blog(conn: Connection,  id: int
                ,  title:str
                , author: str
                , content:str):
    
    try:
        query = f"""
        UPDATE blog 
        SET title = :title , author= :author, content= :content
        where id = :id
        """
        bind_stmt = text(query).bindparams(id=id, title=title, 
                                           author=author, content=content)
        result = conn.execute(bind_stmt)
        # 해당 id로 데이터가 존재하지 않아 update 건수가 없으면 오류를 던진다.
        if result.rowcount == 0:
            raise HTTPException(status_code=status.HTTP_404_NOT_FOUND,
                                detail=f"해당 id {id}는(은) 존재하지 않습니다.")
        conn.commit()
        
    except SQLAlchemyError as e:
        print(e)
        conn.rollback()
        raise HTTPException(status_code=status.HTTP_400_BAD_REQUEST,
                            detail="요청데이터가 제대로 전달되지 않았습니다. ")
    


def delete_blog(conn: Connection, id: int):
    try:
        query = f"""
        DELETE FROM blog
        where id = :id
        """

        bind_stmt = text(query).bindparams(id=id)
        result = conn.execute(bind_stmt)
        # 해당 id로 데이터가 존재하지 않아 delete 건수가 없으면 오류를 던진다.
        if result.rowcount == 0:
            raise HTTPException(status_code=status.HTTP_404_NOT_FOUND,
                                detail=f"해당 id {id}는(은) 존재하지 않습니다.")
        conn.commit()

    except SQLAlchemyError as e:
        print(e)
        conn.rollback()
        raise HTTPException(status_code=status.HTTP_503_SERVICE_UNAVAILABLE,
                            detail="요청하신 서비스가 잠시 내부적으로 문제가 발생하였습니다.")
